2024-03-23 05:36:18 ERROR Traceback (most recent call last):
  File "C:\Users\Abdul Manaf\AppData\Local\Programs\Python\Python39\lib\site-packages\wandb\cli\cli.py", line 103, in wrapper
    return func(*args, **kwargs)
  File "C:\Users\Abdul Manaf\AppData\Local\Programs\Python\Python39\lib\site-packages\wandb\cli\cli.py", line 247, in login
    wandb.login(relogin=relogin, key=key, anonymous=anon_mode, host=host, force=True)
  File "C:\Users\Abdul Manaf\AppData\Local\Programs\Python\Python39\lib\site-packages\wandb\sdk\wandb_login.py", line 77, in login
    configured = _login(**kwargs)
  File "C:\Users\Abdul Manaf\AppData\Local\Programs\Python\Python39\lib\site-packages\wandb\sdk\wandb_login.py", line 298, in _login
    wlogin.prompt_api_key()
  File "C:\Users\Abdul Manaf\AppData\Local\Programs\Python\Python39\lib\site-packages\wandb\sdk\wandb_login.py", line 228, in prompt_api_key
    raise UsageError("api_key not configured (no-tty). call " + directive)
wandb.errors.UsageError: api_key not configured (no-tty). call wandb login [your_api_key]

